<?xml version="1.0" ?>
<robot name="haruna" xmlns:xacro="http://www.ros.org/wiki/xacro">

<!-- <xacro:include filename="$(find haruna_gazebo)/urdf/materials.xacro" /> -->
<xacro:include filename="$(find haruna_gazebo)/urdf/haruna.trans" />
<xacro:include filename="$(find haruna_gazebo)/urdf/haruna.gazebo" />
<link name="base_link">
  <!-- <inertial>
    <origin xyz="1.0338131004861055e-16 5.1690655024305274e-17 0.157" rpy="0 0 0"/>
    <mass value="1.381203895667492"/>
    <inertia ixx="0.019888" iyy="0.023891" izz="0.043779" ixy="0.0" iyz="0.0" ixz="0.0"/>
  </inertial> -->
  <visual>
    <origin xyz="0 0 0" rpy="0 0 0"/>
    <geometry>
      <mesh filename="package://haruna_gazebo/meshes/base_link.stl" scale="0.001 0.001 0.001"/>
    </geometry>
    <!-- <material name="silver"/> -->
  </visual>
  <collision>
    <origin xyz="0 0 0" rpy="0 0 0"/>
    <geometry>
      <mesh filename="package://haruna_gazebo/meshes/base_link.stl" scale="0.001 0.001 0.001"/>
    </geometry>
  </collision>
</link>

<link name="front_leg_link_1">
  <!-- <inertial>
    <origin xyz="0.20000000000000004 0.0 -0.23149999999999998" rpy="0 0 0"/>
    <mass value="0.11774999999999997"/>
    <inertia ixx="0.000222" iyy="0.000222" izz="2e-06" ixy="0.0" iyz="0.0" ixz="0.0"/>
  </inertial> -->
  <visual>
    <origin xyz="-0.0 -0.0 -0.313" rpy="0 0 0"/>
    <geometry>
      <mesh filename="package://haruna_gazebo/meshes/front_leg_link_1.stl" scale="0.001 0.001 0.001"/>
    </geometry>
    <!-- <material name="silver"/> -->
  </visual>
  <collision>
    <origin xyz="-0.0 -0.0 -0.313" rpy="0 0 0"/>
    <geometry>
      <mesh filename="package://haruna_gazebo/meshes/front_leg_link_1.stl" scale="0.001 0.001 0.001"/>
    </geometry>
  </collision>
</link>

<link name="back_leg_link_1">
  <!-- <inertial>
    <origin xyz="-0.2 0.0 -0.23149999999999998" rpy="0 0 0"/>
    <mass value="0.11775"/>
    <inertia ixx="0.000222" iyy="0.000222" izz="2e-06" ixy="0.0" iyz="0.0" ixz="-0.0"/>
  </inertial> -->
  <visual>
    <origin xyz="-0.0 -0.0 -0.313" rpy="0 0 0"/>
    <geometry>
      <mesh filename="package://haruna_gazebo/meshes/back_leg_link_1.stl" scale="0.001 0.001 0.001"/>
    </geometry>
    <!-- <material name="silver"/> -->
  </visual>
  <collision>
    <origin xyz="-0.0 -0.0 -0.313" rpy="0 0 0"/>
    <geometry>
      <mesh filename="package://haruna_gazebo/meshes/back_leg_link_1.stl" scale="0.001 0.001 0.001"/>
    </geometry>
  </collision>
</link>

<link name="right_leg_link_1">
  <!-- <inertial>
    <origin xyz="0.0 -0.10865606936416185 -0.19859393063583816" rpy="0 0 0"/>
    <mass value="0.06790249999999999"/>
    <inertia ixx="3.8e-05" iyy="3.8e-05" izz="2e-06" ixy="-0.0" iyz="-2e-06" ixz="0.0"/>
  </inertial> -->
  <visual>
    <origin xyz="-0.0 -0.0 -0.313" rpy="0 0 0"/>
    <geometry>
      <mesh filename="package://haruna_gazebo/meshes/right_leg_link_1.stl" scale="0.001 0.001 0.001"/>
    </geometry>
    <!-- <material name="silver"/> -->
  </visual>
  <collision>
    <origin xyz="-0.0 -0.0 -0.313" rpy="0 0 0"/>
    <geometry>
      <mesh filename="package://haruna_gazebo/meshes/right_leg_link_1.stl" scale="0.001 0.001 0.001"/>
    </geometry>
  </collision>
</link>

<link name="left_leg_link_1">
  <!-- <inertial>
    <origin xyz="0.0 0.10865606936416185 -0.19859393063583816" rpy="0 0 0"/>
    <mass value="0.06790249999999999"/>
    <inertia ixx="3.8e-05" iyy="3.8e-05" izz="2e-06" ixy="0.0" iyz="2e-06" ixz="0.0"/>
  </inertial> -->
  <visual>
    <origin xyz="-0.0 -0.0 -0.313" rpy="0 0 0"/>
    <geometry>
      <mesh filename="package://haruna_gazebo/meshes/left_leg_link_1.stl" scale="0.001 0.001 0.001"/>
    </geometry>
    <!-- <material name="silver"/> -->
  </visual>
  <collision>
    <origin xyz="-0.0 -0.0 -0.313" rpy="0 0 0"/>
    <geometry>
      <mesh filename="package://haruna_gazebo/meshes/left_leg_link_1.stl" scale="0.001 0.001 0.001"/>
    </geometry>
  </collision>
</link>

<link name="left_wheel_link_1">
  <!-- <inertial>
    <origin xyz="-1.0685163737249417e-17 0.037500000000000006 0.0" rpy="0 0 0"/>
    <mass value="13.363451575437157"/>
    <inertia ixx="0.030402" iyy="0.048275" izz="0.030402" ixy="-0.0" iyz="0.0" ixz="-0.0"/>
  </inertial> -->
  <visual>
    <origin xyz="-0.0 -0.1225 -0.085" rpy="0 0 0"/>
    <geometry>
      <mesh filename="package://haruna_gazebo/meshes/left_wheel_link_1.stl" scale="0.001 0.001 0.001"/>
    </geometry>
    <!-- <material name="silver"/> -->
  </visual>
  <collision>
    <origin xyz="-0.0 -0.1225 -0.085" rpy="0 0 0"/>
    <geometry>
      <mesh filename="package://haruna_gazebo/meshes/left_wheel_link_1.stl" scale="0.001 0.001 0.001"/>
    </geometry>
  </collision>
</link>

<link name="right_wheel_link_1">
  <!-- <inertial>
    <origin xyz="-1.0685163737249417e-17 -0.037500000000000006 0.0" rpy="0 0 0"/>
    <mass value="13.363451575437157"/>
    <inertia ixx="0.030402" iyy="0.048275" izz="0.030402" ixy="-0.0" iyz="-0.0" ixz="-0.0"/>
  </inertial> -->
  <visual>
    <origin xyz="-0.0 0.1225 -0.085" rpy="0 0 0"/>
    <geometry>
      <mesh filename="package://haruna_gazebo/meshes/right_wheel_link_1.stl" scale="0.001 0.001 0.001"/>
    </geometry>
    <!-- <material name="silver"/> -->
  </visual>
  <collision>
    <origin xyz="-0.0 0.1225 -0.085" rpy="0 0 0"/>
    <geometry>
      <mesh filename="package://haruna_gazebo/meshes/right_wheel_link_1.stl" scale="0.001 0.001 0.001"/>
    </geometry>
  </collision>
</link>

<joint name="base_to_front_leg_joint" type="fixed">
  <origin xyz="0.0 0.0 0.313" rpy="0 0 0"/>
  <parent link="base_link"/>
  <child link="front_leg_link_1"/>
</joint>

<joint name="base_to_back_leg_joint" type="fixed">
  <origin xyz="0.0 0.0 0.313" rpy="0 0 0"/>
  <parent link="base_link"/>
  <child link="back_leg_link_1"/>
</joint>

<joint name="base_to_right_leg_joint" type="fixed">
  <origin xyz="0.0 0.0 0.313" rpy="0 0 0"/>
  <parent link="base_link"/>
  <child link="right_leg_link_1"/>
</joint>

<joint name="base_to_left_leg_joint" type="fixed">
  <origin xyz="0.0 0.0 0.313" rpy="0 0 0"/>
  <parent link="base_link"/>
  <child link="left_leg_link_1"/>
</joint>

<joint name="left_leg_to_left_wheel_joint" type="continuous">
  <origin xyz="0.0 0.1225 -0.228" rpy="0 0 0"/>
  <parent link="left_leg_link_1"/>
  <child link="left_wheel_link_1"/>
  <axis xyz="0.0 1.0 0.0"/>
</joint>

<joint name="right_leg_to_right_wheel_joint" type="continuous">
  <origin xyz="0.0 -0.1225 -0.228" rpy="0 0 0"/>
  <parent link="right_leg_link_1"/>
  <child link="right_wheel_link_1"/>
  <axis xyz="0.0 -1.0 0.0"/>
</joint>

</robot>
